File: 数据/xrd/望军4个xrd10分钟-03.22/fe3o4.ras
*RAS_DATA_START
*RAS_HEADER_START
*DISP_FMT_X "%.2f"
*DISP_FMT_Y "%.0f"
*DISP_FULLSCALE "3150.0000000000"
*DISP_LINE_COLOR "255.0000000000"
*DISP_LINE_STYLE "0.0000000000"
*DISP_LINE_WIDTH "0.2500000000"
*DISP_NOTE "Collected Data-100"
*DISP_OFFSET_Y "0.0000000000"
*DISP_PEAKSEARCH_UNIT_Y "cps"
*DISP_RANGE_BOTTOM "0.0000000000"
*DISP_RANGE_LEFT "10.0000000000"
*DISP_RANGE_LOGCUTOFF "0.0100000000"
*DISP_RANGE_RIGHT "90.0000000000"
*DISP_RANGE_TOP "3150.0000000000"
*DISP_SCALE_MODE_Y "0.0000000000"
*DISP_TAB_NAME "Theta/2-Theta"
*DISP_TITLE_Y "Intensity"
*DISP_UNIT_Y "cps"
*DISP_WINDOW_NAME "MSG_MACROENGINE"
*FILE_COMMENT " "
*FILE_MD5 ""
*FILE_MEMO " "
*FILE_OPERATOR "administrator"
*FILE_PART_ID "MEAS_PBEA_00223"
*FILE_SAMPLE " "
*FILE_TYPE "RAS_RAW"
*FILE_USERGROUP "System Manager"
*FILE_VERSION "1.0000000000"
*HW_ATTACHMENT_ID "ATT0106"
*HW_ATTACHMENT_NAME "汎用雰囲気セパレータ|Air-sensitive Sample Holder"
*HW_COUNTER_ID-0 "CUT0025"
*HW_COUNTER_ID-1 "CUT0020"
*HW_COUNTER_ID-2 "CUT0020"
*HW_COUNTER_ID-3 "CMC0021"
*HW_COUNTER_NAME-0 "D/teX Ultra2|D/teX Ultra2"
*HW_COUNTER_NAME-1 "None|None"
*HW_COUNTER_NAME-2 "None|None"
*HW_COUNTER_NAME-3 "検出器モノクロメータ|Detector monochromator"
*HW_COUNTER_SELECT_NAME "D/teX Ultra2|D/teX Ultra2"
*HW_GONIOMETER_ID "GON0070"
*HW_GONIOMETER_NAME "MiniFlex 300/600|MiniFlex 300/600"
*HW_GONIOMETER_RADIUS-0 "79.0"
*HW_GONIOMETER_RADIUS-1 "91.5"
*HW_GONIOMETER_RADIUS-2 "150.0"
*HW_GONIOMETER_RADIUS-3 "0"
*HW_GONIOMETER_RADIUS-4 "92.7"
*HW_GONIOMETER_RADIUS-5 "139.3"
*HW_GONIOMETER_RADIUS-6 "46.6"
*HW_GONIOMETER_RADIUS-7 "150.0"
*HW_I_OPT_ID-0 "ISL0021"
*HW_I_OPT_ID-1 "ISO0021"
*HW_I_OPT_NAME-0 "発散スリット|Divergence slit"
*HW_I_OPT_NAME-1 "入射平行スリット|Incident parallel slit"
*HW_R_ATTENUATER_AUTOMODE "0"
*HW_R_OPT_ID-0 "RSS0021"
*HW_R_OPT_ID-1 "RSO0021"
*HW_R_OPT_ID-2 "RRS0021"
*HW_R_OPT_NAME-0 "散乱スリット|Scattering slit"
*HW_R_OPT_NAME-1 "受光平行スリット|Receiving soller slit"
*HW_R_OPT_NAME-2 "受光スリット|Receiving slit"
*HW_SAMPLE_HOLDER_ID "SMP0000"
*HW_SAMPLE_HOLDER_NAME "無し|None"
*HW_XG_CURRENT_MAX "15"
*HW_XG_CURRENT_MIN "2"
*HW_XG_CURRENT_RESOLUTION "1"
*HW_XG_CURRENT_UNIT "mA"
*HW_XG_FOCUS "1mm x 10mm"
*HW_XG_FOCUS_TYPE "Normal"
*HW_XG_ID "1060"
*HW_XG_NAME "300W/600W 封入管-B|300W/600W Sealed tube-B"
*HW_XG_TARGET_ATOMIC_NUMBER "29.0000000000"
*HW_XG_TARGET_NAME "Cu"
*HW_XG_TYPE "Hermetic"
*HW_XG_VOLTAGE_MAX "40"
*HW_XG_VOLTAGE_MIN "20"
*HW_XG_VOLTAGE_RESOLUTION "1"
*HW_XG_VOLTAGE_UNIT "kV"
*HW_XG_WATT_MAX "0.600"
*HW_XG_WATT_UNIT "kW"
*HW_XG_WAVE_LENGTH_ALPHA1 "1.540593"
*HW_XG_WAVE_LENGTH_ALPHA2 "1.544414"
*HW_XG_WAVE_LENGTH_BETA "1.392250"
*MEAS_COND_AXIS_NAME-0 "Theta/2-Theta"
*MEAS_COND_AXIS_NAME-1 "Soller(inc.)"
*MEAS_COND_AXIS_NAME-2 "IHS"
*MEAS_COND_AXIS_NAME-3 "DS"
*MEAS_COND_AXIS_NAME-4 "SS"
*MEAS_COND_AXIS_NAME-5 "Soller(rec.)"
*MEAS_COND_AXIS_NAME-6 "RS"
*MEAS_COND_AXIS_NAME-7 "Filter"
*MEAS_COND_AXIS_NAME-8 "Monochromator"
*MEAS_COND_AXIS_NAME-9 "PHA"
*MEAS_COND_AXIS_NAME_INTERNAL-0 "TwoThetaTheta"
*MEAS_COND_AXIS_NAME_INTERNAL-1 "IncidentSollerSlit"
*MEAS_COND_AXIS_NAME_INTERNAL-2 "IncidentAxdSlit"
*MEAS_COND_AXIS_NAME_INTERNAL-3 "IncidentSlitBox"
*MEAS_COND_AXIS_NAME_INTERNAL-4 "ReceivingSlitBox1"
*MEAS_COND_AXIS_NAME_INTERNAL-5 "ReceivingSollerSlit"
*MEAS_COND_AXIS_NAME_INTERNAL-6 "ReceivingSlitBox2"
*MEAS_COND_AXIS_NAME_INTERNAL-7 "Filter"
*MEAS_COND_AXIS_NAME_INTERNAL-8 "CounterMonochromator"
*MEAS_COND_AXIS_NAME_INTERNAL-9 "PHA"
*MEAS_COND_AXIS_NAME_MAGICNO-0 "268632064.0000000000"
*MEAS_COND_AXIS_NAME_MAGICNO-1 "20971521.0000000000"
*MEAS_COND_AXIS_NAME_MAGICNO-2 "22020097.0000000000"
*MEAS_COND_AXIS_NAME_MAGICNO-3 "22020097.0000000000"
*MEAS_COND_AXIS_NAME_MAGICNO-4 "23068673.0000000000"
*MEAS_COND_AXIS_NAME_MAGICNO-5 "20971521.0000000000"
*MEAS_COND_AXIS_NAME_MAGICNO-6 "23068673.0000000000"
*MEAS_COND_AXIS_NAME_MAGICNO-7 "20971521.0000000000"
*MEAS_COND_AXIS_NAME_MAGICNO-8 "20971521.0000000000"
*MEAS_COND_AXIS_NAME_MAGICNO-9 "0.0000000000"
*MEAS_COND_AXIS_OFFSET-0 "0.0000000000"
*MEAS_COND_AXIS_OFFSET-1 "-"
*MEAS_COND_AXIS_OFFSET-2 "-"
*MEAS_COND_AXIS_OFFSET-3 "-"
*MEAS_COND_AXIS_OFFSET-4 "-"
*MEAS_COND_AXIS_OFFSET-5 "-"
*MEAS_COND_AXIS_OFFSET-6 "-"
*MEAS_COND_AXIS_OFFSET-7 "-"
*MEAS_COND_AXIS_OFFSET-8 "-"
*MEAS_COND_AXIS_OFFSET-9 "-"
*MEAS_COND_AXIS_POSITION-0 "12.0000000000"
*MEAS_COND_AXIS_POSITION-1 "5.0deg"
*MEAS_COND_AXIS_POSITION-2 "10.0mm"
*MEAS_COND_AXIS_POSITION-3 "1.250deg"
*MEAS_COND_AXIS_POSITION-4 "8.0mm"
*MEAS_COND_AXIS_POSITION-5 "5.0deg"
*MEAS_COND_AXIS_POSITION-6 "0.3mm"
*MEAS_COND_AXIS_POSITION-7 "K-beta(x1.5)"
*MEAS_COND_AXIS_POSITION-8 "None"
*MEAS_COND_AXIS_POSITION-9 "46.0000000000"
*MEAS_COND_AXIS_UNIT-0 "deg"
*MEAS_COND_AXIS_UNIT-1 ""
*MEAS_COND_AXIS_UNIT-2 ""
*MEAS_COND_AXIS_UNIT-3 ""
*MEAS_COND_AXIS_UNIT-4 ""
*MEAS_COND_AXIS_UNIT-5 ""
*MEAS_COND_AXIS_UNIT-6 ""
*MEAS_COND_AXIS_UNIT-7 ""
*MEAS_COND_AXIS_UNIT-8 ""
*MEAS_COND_AXIS_UNIT-9 "div"
*MEAS_COND_COUNTER_CNTLOSS_CORR "0.0000000000"
*MEAS_COND_COUNTER_PHABASE "46.0000000000"
*MEAS_COND_COUNTER_PHAWINDOW "8.0000000000"
*MEAS_COND_COUNTER_PHA_UNIT "div"
*MEAS_COND_COUNTER_TAUDIFF "0.2500000000"
*MEAS_COND_COUNTER_TAUINT "0.7500000000"
*MEAS_COND_IRRADIATION_MODE "OFF"
*MEAS_COND_IRRADIATION_WIDTH ""
*MEAS_COND_OPT_ATTR " "
*MEAS_COND_OPT_NAME ""
*MEAS_COND_UNSYMMETRIC_MODE "OFF"
*MEAS_COND_XG_CURRENT "15.0000000000"
*MEAS_COND_XG_VOLTAGE "40.0000000000"
*MEAS_COND_XG_WAVE_TYPE "Ka"
*MEAS_DATA_COUNT "4001.0000000000"
*MEAS_SCAN_AXIS_X "Theta/2-Theta"
*MEAS_SCAN_AXIS_X_INTERNAL "TwoThetaTheta"
*MEAS_SCAN_END_TIME "03/24/23 00:34:35"
*MEAS_SCAN_MODE "CONTINUOUS"
*MEAS_SCAN_MONITOR "0"
*MEAS_SCAN_RESOLUTION_X "0.0025"
*MEAS_SCAN_SPEED "90.000000"
*MEAS_SCAN_SPEED_UNIT "deg/min"
*MEAS_SCAN_SPEED_USER "90.000000"
*MEAS_SCAN_START "10.0000000000"
*MEAS_SCAN_START_TIME "03/24/23 00:33:21"
*MEAS_SCAN_STEP "0.0200000000"
*MEAS_SCAN_STOP "90.0000000000"
*MEAS_SCAN_UNIT_X "deg"
*MEAS_SCAN_UNIT_Y "counts"
*SLIT_SYSTEM "0"
*RAS_HEADER_END
*RAS_INT_START
10.0000 2.0000 1.0000
10.0600 6.0000 1.0000
10.1200 2.0000 1.0000
10.1800 6.0000 1.0000
10.2400 5.0000 1.0000
10.3000 4.0000 1.0000
10.3600 5.0000 1.0000
10.4200 2.0000 1.0000
10.4800 4.0000 1.0000
10.5400 5.0000 1.0000
10.6000 6.0000 1.0000
10.6600 6.0000 1.0000
10.7200 2.0000 1.0000
10.7800 4.0000 1.0000
10.8400 1.0000 1.0000
10.9000 10.0000 1.0000
10.9600 12.0000 1.0000
11.0200 5.0000 1.0000
11.0800 6.0000 1.0000
11.1400 3.0000 1.0000
11.2000 2.0000 1.0000
11.2600 4.0000 1.0000
11.3200 9.0000 1.0000
11.3800 3.0000 1.0000
11.4400 5.0000 1.0000
11.5000 4.0000 1.0000
11.5600 6.0000 1.0000
11.6200 3.0000 1.0000
11.6800 3.0000 1.0000
11.7400 7.0000 1.0000
11.8000 3.0000 1.0000
11.8600 5.0000 1.0000
11.9200 4.0000 1.0000
11.9800 6.0000 1.0000
12.0400 11.0000 1.0000
12.1000 4.0000 1.0000
12.1600 5.0000 1.0000
12.2200 6.0000 1.0000
12.2800 4.0000 1.0000
12.3400 9.0000 1.0000
12.4000 3.0000 1.0000
12.4600 5.0000 1.0000
12.5200 9.0000 1.0000
12.5800 7.0000 1.0000
12.6400 2.0000 1.0000
12.7000 4.0000 1.0000
12.7600 8.0000 1.0000
12.8200 4.0000 1.0000
12.8800 4.0000 1.0000
12.9400 5.0000 1.0000
13.0000 3.0000 1.0000
13.0600 3.0000 1.0000
13.1200 7.0000 1.0000
13.1800 2.0000 1.0000
13.2400 8.0000 1.0000
13.3000 3.0000 1.0000
13.3600 6.0000 1.0000
13.4200 9.0000 1.0000
13.4800 8.0000 1.0000
13.5400 13.0000 1.0000
13.6000 5.0000 1.0000
13.6600 5.0000 1.0000
13.7200 7.0000 1.0000
13.7800 5.0000 1.0000
13.8400 8.0000 1.0000
13.9000 12.0000 1.0000
13.9600 4.0000 1.0000
14.0200 7.0000 1.0000
14.0800 6.0000 1.0000
14.1400 8.0000 1.0000
14.2000 5.0000 1.0000
14.2600 2.0000 1.0000
14.3200 11.0000 1.0000
14.3800 10.0000 1.0000
14.4400 9.0000 1.0000
14.5000 2.0000 1.0000
14.5600 8.0000 1.0000
14.6200 6.0000 1.0000
14.6800 9.0000 1.0000
14.7400 5.0000 1.0000
14.8000 6.0000 1.0000
14.8600 4.0000 1.0000
14.9200 10.0000 1.0000
14.9800 10.0000 1.0000
15.0400 7.0000 1.0000
15.1000 7.0000 1.0000
15.1600 8.0000 1.0000
15.2200 8.0000 1.0000
15.2800 8.0000 1.0000
15.3400 6.0000 1.0000
15.4000 3.0000 1.0000
15.4600 5.0000 1.0000
15.5200 2.0000 1.0000
15.5800 4.0000 1.0000
15.6400 10.0000 1.0000
15.7000 11.0000 1.0000
15.7600 5.0000 1.0000
15.8200 7.0000 1.0000
15.8800 5.0000 1.0000
15.9400 2.0000 1.0000
16.0000 4.0000 1.0000
16.0600 7.0000 1.0000
16.1200 6.0000 1.0000
16.1800 5.0000 1.0000
16.2400 11.0000 1.0000
16.3000 6.0000 1.0000
16.3600 5.0000 1.0000
16.4200 8.0000 1.0000
16.4800 5.0000 1.0000
16.5400 16.0000 1.0000
16.6000 6.0000 1.0000
16.6600 9.0000 1.0000
16.7200 5.0000 1.0000
16.7800 4.0000 1.0000
16.8400 4.0000 1.0000
16.9000 13.0000 1.0000
16.9600 7.0000 1.0000
17.0200 10.0000 1.0000
17.0800 6.0000 1.0000
17.1400 6.0000 1.0000
17.2000 6.0000 1.0000
17.2600 6.0000 1.0000
17.3200 5.0000 1.0000
17.3800 2.0000 1.0000
17.4400 3.0000 1.0000
17.5000 6.0000 1.0000
17.5600 7.0000 1.0000
17.6200 7.0000 1.0000
17.6800 9.0000 1.0000
17.7400 6.0000 1.0000
17.8000 5.0000 1.0000
17.8600 7.0000 1.0000
17.9200 8.0000 1.0000
17.9800 7.0000 1.0000
18.0400 7.0000 1.0000
18.1000 8.0000 1.0000
18.1600 5.0000 1.0000
18.2200 13.0000 1.0000
18.2800 6.0000 1.0000
18.3400 9.0000 1.0000
18.4000 10.0000 1.0000
18.4600 15.0000 1.0000
18.5200 6.0000 1.0000
18.5800 8.0000 1.0000
18.6400 6.0000 1.0000
18.7000 7.0000 1.0000
18.7600 10.0000 1.0000
18.8200 8.0000 1.0000
18.8800 12.0000 1.0000
18.9400 10.0000 1.0000
19.0000 9.0000 1.0000
19.0600 8.0000 1.0000
19.1200 10.0000 1.0000
19.1800 10.0000 1.0000
19.2400 9.0000 1.0000
19.3000 7.0000 1.0000
19.3600 10.0000 1.0000
19.4200 11.0000 1.0000
19.4800 14.0000 1.0000
19.5400 10.0000 1.0000
19.6000 13.0000 1.0000
19.6600 8.0000 1.0000
19.7200 7.0000 1.0000
19.7800 7.0000 1.0000
19.8400 11.0000 1.0000
19.9000 6.0000 1.0000
19.9600 5.0000 1.0000
20.0200 6.0000 1.0000
20.0800 10.0000 1.0000
20.1400 8.0000 1.0000
20.2000 11.0000 1.0000
20.2600 3.0000 1.0000
20.3200 8.0000 1.0000
20.3800 7.0000 1.0000
20.4400 15.0000 1.0000
20.5000 11.0000 1.0000
20.5600 14.0000 1.0000
20.6200 10.0000 1.0000
20.6800 8.0000 1.0000
20.7400 13.0000 1.0000
20.8000 8.0000 1.0000
20.8600 12.0000 1.0000
20.9200 9.0000 1.0000
20.9800 12.0000 1.0000
21.0400 9.0000 1.0000
21.1000 11.0000 1.0000
21.1600 11.0000 1.0000
21.2200 9.0000 1.0000
21.2800 8.0000 1.0000
21.3400 13.0000 1.0000
21.4000 8.0000 1.0000
21.4600 11.0000 1.0000
21.5200 10.0000 1.0000
21.5800 16.0000 1.0000
21.6400 3.0000 1.0000
21.7000 11.0000 1.0000
21.7600 12.0000 1.0000
21.8200 10.0000 1.0000
21.8800 4.0000 1.0000
21.9400 6.0000 1.0000
22.0000 16.0000 1.0000
22.0600 18.0000 1.0000
22.1200 8.0000 1.0000
22.1800 13.0000 1.0000
22.2400 14.0000 1.0000
22.3000 9.0000 1.0000
22.3600 10.0000 1.0000
22.4200 9.0000 1.0000
22.4800 8.0000 1.0000
22.5400 7.0000 1.0000
22.6000 13.0000 1.0000
22.6600 11.0000 1.0000
22.7200 10.0000 1.0000
22.7800 11.0000 1.0000
22.8400 9.0000 1.0000
22.9000 10.0000 1.0000
22.9600 8.0000 1.0000
23.0200 9.0000 1.0000
23.0800 10.0000 1.0000
23.1400 8.0000 1.0000
23.2000 5.0000 1.0000
23.2600 14.0000 1.0000
23.3200 9.0000 1.0000
23.3800 7.0000 1.0000
23.4400 9.0000 1.0000
23.5000 7.0000 1.0000
23.5600 12.0000 1.0000
23.6200 12.0000 1.0000
23.6800 9.0000 1.0000
23.7400 13.0000 1.0000
23.8000 16.0000 1.0000
23.8600 12.0000 1.0000
23.9200 11.0000 1.0000
23.9800 6.0000 1.0000
24.0400 13.0000 1.0000
24.1000 12.0000 1.0000
24.1600 18.0000 1.0000
24.2200 14.0000 1.0000
24.2800 11.0000 1.0000
24.3400 10.0000 1.0000
24.4000 11.0000 1.0000
24.4600 13.0000 1.0000
24.5200 10.0000 1.0000
24.5800 11.0000 1.0000
24.6400 11.0000 1.0000
24.7000 8.0000 1.0000
24.7600 12.0000 1.0000
24.8200 13.0000 1.0000
24.8800 7.0000 1.0000
24.9400 9.0000 1.0000
25.0000 7.0000 1.0000
25.0600 7.0000 1.0000
25.1200 10.0000 1.0000
25.1800 10.0000 1.0000
25.2400 3.0000 1.0000
25.3000 10.0000 1.0000
25.3600 5.0000 1.0000
25.4200 14.0000 1.0000
25.4800 8.0000 1.0000
25.5400 13.0000 1.0000
25.6000 18.0000 1.0000
25.6600 4.0000 1.0000
25.7200 7.0000 1.0000
25.7800 4.0000 1.0000
25.8400 6.0000 1.0000
25.9000 7.0000 1.0000
25.9600 6.0000 1.0000
26.0200 9.0000 1.0000
26.0800 9.0000 1.0000
26.1400 7.0000 1.0000
26.2000 16.0000 1.0000
26.2600 7.0000 1.0000
26.3200 14.0000 1.0000
26.3800 4.0000 1.0000
26.4400 9.0000 1.0000
26.5000 13.0000 1.0000
26.5600 7.0000 1.0000
26.6200 13.0000 1.0000
26.6800 9.0000 1.0000
26.7400 4.0000 1.0000
26.8000 13.0000 1.0000
26.8600 8.0000 1.0000
26.9200 7.0000 1.0000
26.9800 10.0000 1.0000
27.0400 10.0000 1.0000
27.1000 6.0000 1.0000
27.1600 9.0000 1.0000
27.2200 12.0000 1.0000
27.2800 5.0000 1.0000
27.3400 10.0000 1.0000
27.4000 10.0000 1.0000
27.4600 8.0000 1.0000
27.5200 13.0000 1.0000
27.5800 5.0000 1.0000
27.6400 9.0000 1.0000
27.7000 8.0000 1.0000
27.7600 7.0000 1.0000
27.8200 7.0000 1.0000
27.8800 7.0000 1.0000
27.9400 4.0000 1.0000
28.0000 7.0000 1.0000
28.0600 16.0000 1.0000
28.1200 10.0000 1.0000
28.1800 9.0000 1.0000
28.2400 4.0000 1.0000
28.3000 7.0000 1.0000
28.3600 10.0000 1.0000
28.4200 8.0000 1.0000
28.4800 3.0000 1.0000
28.5400 9.0000 1.0000
28.6000 7.0000 1.0000
28.6600 7.0000 1.0000
28.7200 7.0000 1.0000
28.7800 6.0000 1.0000
28.8400 11.0000 1.0000
28.9000 6.0000 1.0000
28.9600 8.0000 1.0000
29.0200 8.0000 1.0000
29.0800 10.0000 1.0000
29.1400 8.0000 1.0000
29.2000 8.0000 1.0000
29.2600 7.0000 1.0000
29.3200 5.0000 1.0000
29.3800 6.0000 1.0000
29.4400 7.0000 1.0000
29.5000 8.0000 1.0000
29.5600 2.0000 1.0000
29.6200 6.0000 1.0000
29.6800 5.0000 1.0000
29.7400 5.0000 1.0000
29.8000 10.0000 1.0000
29.8600 7.0000 1.0000
29.9200 4.0000 1.0000
29.9800 7.0000 1.0000
30.0400 2.0000 1.0000
30.1000 12.0000 1.0000
30.1600 10.0000 1.0000
30.2200 7.0000 1.0000
30.2800 2.0000 1.0000
30.3400 7.0000 1.0000
30.4000 9.0000 1.0000
30.4600 3.0000 1.0000
30.5200 6.0000 1.0000
30.5800 7.0000 1.0000
30.6400 5.0000 1.0000
30.7000 6.0000 1.0000
30.7600 7.0000 1.0000
30.8200 13.0000 1.0000
30.8800 4.0000 1.0000
30.9400 4.0000 1.0000
31.0000 7.0000 1.0000
31.0600 5.0000 1.0000
31.1200 8.0000 1.0000
31.1800 5.0000 1.0000
31.2400 5.0000 1.0000
31.3000 5.0000 1.0000
31.3600 7.0000 1.0000
31.4200 3.0000 1.0000
31.4800 10.0000 1.0000
31.5400 4.0000 1.0000
31.6000 6.0000 1.0000
31.6600 4.0000 1.0000
31.7200 3.0000 1.0000
31.7800 5.0000 1.0000
31.8400 2.0000 1.0000
31.9000 3.0000 1.0000
31.9600 4.0000 1.0000
32.0200 8.0000 1.0000
32.0800 3.0000 1.0000
32.1400 6.0000 1.0000
32.2000 8.0000 1.0000
32.2600 7.0000 1.0000
32.3200 3.0000 1.0000
32.3800 9.0000 1.0000
32.4400 8.0000 1.0000
32.5000 7.0000 1.0000
32.5600 7.0000 1.0000
32.6200 5.0000 1.0000
32.6800 12.0000 1.0000
32.7400 6.0000 1.0000
32.8000 10.0000 1.0000
32.8600 16.0000 1.0000
32.9200 16.0000 1.0000
32.9800 22.0000 1.0000
33.0400 28.0000 1.0000
33.1000 35.0000 1.0000
33.1600 23.0000 1.0000
33.2200 28.0000 1.0000
33.2800 21.0000 1.0000
33.3400 20.0000 1.0000
33.4000 17.0000 1.0000
33.4600 10.0000 1.0000
33.5200 10.0000 1.0000
33.5800 9.0000 1.0000
33.6400 8.0000 1.0000
33.7000 8.0000 1.0000
33.7600 6.0000 1.0000
33.8200 8.0000 1.0000
33.8800 8.0000 1.0000
33.9400 7.0000 1.0000
34.0000 10.0000 1.0000
34.0600 6.0000 1.0000
34.1200 6.0000 1.0000
34.1800 8.0000 1.0000
34.2400 4.0000 1.0000
34.3000 4.0000 1.0000
34.3600 9.0000 1.0000
34.4200 8.0000 1.0000
34.4800 7.0000 1.0000
34.5400 5.0000 1.0000
34.6000 4.0000 1.0000
34.6600 6.0000 1.0000
34.7200 6.0000 1.0000
34.7800 4.0000 1.0000
34.8400 7.0000 1.0000
34.9000 6.0000 1.0000
34.9600 3.0000 1.0000
35.0200 4.0000 1.0000
35.0800 7.0000 1.0000
35.1400 7.0000 1.0000
35.2000 6.0000 1.0000
35.2600 9.0000 1.0000
35.3200 16.0000 1.0000
35.3800 15.0000 1.0000
35.4400 20.0000 1.0000
35.5000 16.0000 1.0000
35.5600 20.0000 1.0000
35.6200 22.0000 1.0000
35.6800 11.0000 1.0000
35.7400 10.0000 1.0000
35.8000 20.0000 1.0000
35.8600 17.0000 1.0000
35.9200 11.0000 1.0000
35.9800 10.0000 1.0000
36.0400 10.0000 1.0000
36.1000 8.0000 1.0000
36.1600 3.0000 1.0000
36.2200 12.0000 1.0000
36.2800 9.0000 1.0000
36.3400 9.0000 1.0000
36.4000 5.0000 1.0000
36.4600 5.0000 1.0000
36.5200 7.0000 1.0000
36.5800 14.0000 1.0000
36.6400 7.0000 1.0000
36.7000 4.0000 1.0000
36.7600 2.0000 1.0000
36.8200 6.0000 1.0000
36.8800 6.0000 1.0000
36.9400 5.0000 1.0000
37.0000 7.0000 1.0000
37.0600 7.0000 1.0000
37.1200 4.0000 1.0000
37.1800 4.0000 1.0000
37.2400 8.0000 1.0000
37.3000 6.0000 1.0000
37.3600 8.0000 1.0000
37.4200 2.0000 1.0000
37.4800 7.0000 1.0000
37.5400 5.0000 1.0000
37.6000 6.0000 1.0000
37.6600 5.0000 1.0000
37.7200 4.0000 1.0000
37.7800 5.0000 1.0000
37.8400 6.0000 1.0000
37.9000 10.0000 1.0000
37.9600 4.0000 1.0000
38.0200 6.0000 1.0000
38.0800 9.0000 1.0000
38.1400 6.0000 1.0000
38.2000 3.0000 1.0000
38.2600 6.0000 1.0000
38.3200 5.0000 1.0000
38.3800 6.0000 1.0000
38.4400 10.0000 1.0000
38.5000 2.0000 1.0000
38.5600 7.0000 1.0000
38.6200 7.0000 1.0000
38.6800 4.0000 1.0000
38.7400 3.0000 1.0000
38.8000 9.0000 1.0000
38.8600 5.0000 1.0000
38.9200 8.0000 1.0000
38.9800 6.0000 1.0000
39.0400 4.0000 1.0000
39.1000 7.0000 1.0000
39.1600 7.0000 1.0000
39.2200 4.0000 1.0000
39.2800 2.0000 1.0000
39.3400 7.0000 1.0000
39.4000 5.0000 1.0000
39.4600 11.0000 1.0000
39.5200 10.0000 1.0000
39.5800 8.0000 1.0000
39.6400 3.0000 1.0000
39.7000 3.0000 1.0000
39.7600 6.0000 1.0000
39.8200 6.0000 1.0000
39.8800 4.0000 1.0000
39.9400 2.0000 1.0000
40.0000 1.0000 1.0000
40.0600 3.0000 1.0000
40.1200 4.0000 1.0000
40.1800 3.0000 1.0000
40.2400 6.0000 1.0000
40.3000 8.0000 1.0000
40.3600 6.0000 1.0000
40.4200 8.0000 1.0000
40.4800 6.0000 1.0000
40.5400 8.0000 1.0000
40.6000 6.0000 1.0000
40.6600 10.0000 1.0000
40.7200 9.0000 1.0000
40.7800 8.0000 1.0000
40.8400 9.0000 1.0000
40.9000 5.0000 1.0000
40.9600 9.0000 1.0000
41.0200 8.0000 1.0000
41.0800 7.0000 1.0000
41.1400 6.0000 1.0000
41.2000 7.0000 1.0000
41.2600 6.0000 1.0000
41.3200 4.0000 1.0000
41.3800 2.0000 1.0000
41.4400 6.0000 1.0000
41.5000 1.0000 1.0000
41.5600 5.0000 1.0000
41.6200 7.0000 1.0000
41.6800 6.0000 1.0000
41.7400 7.0000 1.0000
41.8000 4.0000 1.0000
41.8600 5.0000 1.0000
41.9200 4.0000 1.0000
41.9800 9.0000 1.0000
42.0400 4.0000 1.0000
42.1000 4.0000 1.0000
42.1600 2.0000 1.0000
42.2200 5.0000 1.0000
42.2800 13.0000 1.0000
42.3400 5.0000 1.0000
42.4000 10.0000 1.0000
42.4600 4.0000 1.0000
42.5200 4.0000 1.0000
42.5800 7.0000 1.0000
42.6400 4.0000 1.0000
42.7000 2.0000 1.0000
42.7600 5.0000 1.0000
42.8200 2.0000 1.0000
42.8800 6.0000 1.0000
42.9400 4.0000 1.0000
43.0000 6.0000 1.0000
43.0600 2.0000 1.0000
43.1200 4.0000 1.0000
43.1800 4.0000 1.0000
43.2400 4.0000 1.0000
43.3000 3.0000 1.0000
43.3600 4.0000 1.0000
43.4200 6.0000 1.0000
43.4800 7.0000 1.0000
43.5400 7.0000 1.0000
43.6000 3.0000 1.0000
43.6600 3.0000 1.0000
43.7200 0.0000 1.0000
43.7800 6.0000 1.0000
43.8400 6.0000 1.0000
43.9000 9.0000 1.0000
43.9600 10.0000 1.0000
44.0200 2.0000 1.0000
44.0800 4.0000 1.0000
44.1400 4.0000 1.0000
44.2000 4.0000 1.0000
44.2600 7.0000 1.0000
44.3200 8.0000 1.0000
44.3800 6.0000 1.0000
44.4400 4.0000 1.0000
44.5000 2.0000 1.0000
44.5600 9.0000 1.0000
44.6200 8.0000 1.0000
44.6800 8.0000 1.0000
44.7400 3.0000 1.0000
44.8000 2.0000 1.0000
44.8600 1.0000 1.0000
44.9200 1.0000 1.0000
44.9800 5.0000 1.0000
45.0400 6.0000 1.0000
45.1000 5.0000 1.0000
45.1600 6.0000 1.0000
45.2200 5.0000 1.0000
45.2800 5.0000 1.0000
45.3400 8.0000 1.0000
45.4000 1.0000 1.0000
45.4600 5.0000 1.0000
45.5200 4.0000 1.0000
45.5800 5.0000 1.0000
45.6400 2.0000 1.0000
45.7000 5.0000 1.0000
45.7600 4.0000 1.0000
45.8200 5.0000 1.0000
45.8800 4.0000 1.0000
45.9400 6.0000 1.0000
46.0000 2.0000 1.0000
46.0600 3.0000 1.0000
46.1200 2.0000 1.0000
46.1800 6.0000 1.0000
46.2400 8.0000 1.0000
46.3000 3.0000 1.0000
46.3600 6.0000 1.0000
46.4200 3.0000 1.0000
46.4800 6.0000 1.0000
46.5400 3.0000 1.0000
46.6000 1.0000 1.0000
46.6600 3.0000 1.0000
46.7200 4.0000 1.0000
46.7800 7.0000 1.0000
46.8400 4.0000 1.0000
46.9000 5.0000 1.0000
46.9600 8.0000 1.0000
47.0200 6.0000 1.0000
47.0800 4.0000 1.0000
47.1400 2.0000 1.0000
47.2000 6.0000 1.0000
47.2600 8.0000 1.0000
47.3200 4.0000 1.0000
47.3800 3.0000 1.0000
47.4400 5.0000 1.0000
47.5000 8.0000 1.0000
47.5600 4.0000 1.0000
47.6200 4.0000 1.0000
47.6800 8.0000 1.0000
47.7400 5.0000 1.0000
47.8000 6.0000 1.0000
47.8600 9.0000 1.0000
47.9200 4.0000 1.0000
47.9800 4.0000 1.0000
48.0400 7.0000 1.0000
48.1000 3.0000 1.0000
48.1600 5.0000 1.0000
48.2200 6.0000 1.0000
48.2800 5.0000 1.0000
48.3400 5.0000 1.0000
48.4000 5.0000 1.0000
48.4600 4.0000 1.0000
48.5200 3.0000 1.0000
48.5800 3.0000 1.0000
48.6400 6.0000 1.0000
48.7000 5.0000 1.0000
48.7600 5.0000 1.0000
48.8200 5.0000 1.0000
48.8800 9.0000 1.0000
48.9400 6.0000 1.0000
49.0000 3.0000 1.0000
49.0600 8.0000 1.0000
49.1200 8.0000 1.0000
49.1800 7.0000 1.0000
49.2400 14.0000 1.0000
49.3000 11.0000 1.0000
49.3600 19.0000 1.0000
49.4200 16.0000 1.0000
49.4800 11.0000 1.0000
49.5400 17.0000 1.0000
49.6000 11.0000 1.0000
49.6600 12.0000 1.0000
49.7200 10.0000 1.0000
49.7800 10.0000 1.0000
49.8400 9.0000 1.0000
49.9000 7.0000 1.0000
49.9600 9.0000 1.0000
50.0200 6.0000 1.0000
50.0800 4.0000 1.0000
50.1400 8.0000 1.0000
50.2000 9.0000 1.0000
50.2600 4.0000 1.0000
50.3200 6.0000 1.0000
50.3800 5.0000 1.0000
50.4400 2.0000 1.0000
50.5000 3.0000 1.0000
50.5600 2.0000 1.0000
50.6200 8.0000 1.0000
50.6800 3.0000 1.0000
50.7400 10.0000 1.0000
50.8000 5.0000 1.0000
50.8600 3.0000 1.0000
50.9200 6.0000 1.0000
50.9800 9.0000 1.0000
51.0400 6.0000 1.0000
51.1000 8.0000 1.0000
51.1600 2.0000 1.0000
51.2200 8.0000 1.0000
51.2800 5.0000 1.0000
51.3400 6.0000 1.0000
51.4000 3.0000 1.0000
51.4600 8.0000 1.0000
51.5200 7.0000 1.0000
51.5800 5.0000 1.0000
51.6400 6.0000 1.0000
51.7000 3.0000 1.0000
51.7600 5.0000 1.0000
51.8200 3.0000 1.0000
51.8800 11.0000 1.0000
51.9400 7.0000 1.0000
52.0000 5.0000 1.0000
52.0600 1.0000 1.0000
52.1200 8.0000 1.0000
52.1800 6.0000 1.0000
52.2400 3.0000 1.0000
52.3000 6.0000 1.0000
52.3600 7.0000 1.0000
52.4200 6.0000 1.0000
52.4800 7.0000 1.0000
52.5400 8.0000 1.0000
52.6000 2.0000 1.0000
52.6600 7.0000 1.0000
52.7200 4.0000 1.0000
52.7800 5.0000 1.0000
52.8400 7.0000 1.0000
52.9000 2.0000 1.0000
52.9600 7.0000 1.0000
53.0200 0.0000 1.0000
53.0800 2.0000 1.0000
53.1400 4.0000 1.0000
53.2000 11.0000 1.0000
53.2600 9.0000 1.0000
53.3200 5.0000 1.0000
53.3800 9.0000 1.0000
53.4400 6.0000 1.0000
53.5000 7.0000 1.0000
53.5600 6.0000 1.0000
53.6200 7.0000 1.0000
53.6800 9.0000 1.0000
53.7400 10.0000 1.0000
53.8000 7.0000 1.0000
53.8600 12.0000 1.0000
53.9200 15.0000 1.0000
53.9800 22.0000 1.0000
54.0400 22.0000 1.0000
54.1000 15.0000 1.0000
54.1600 13.0000 1.0000
54.2200 15.0000 1.0000
54.2800 9.0000 1.0000
54.3400 13.0000 1.0000
54.4000 6.0000 1.0000
54.4600 9.0000 1.0000
54.5200 8.0000 1.0000
54.5800 6.0000 1.0000
54.6400 7.0000 1.0000
54.7000 4.0000 1.0000
54.7600 4.0000 1.0000
54.8200 2.0000 1.0000
54.8800 8.0000 1.0000
54.9400 7.0000 1.0000
55.0000 2.0000 1.0000
55.0600 6.0000 1.0000
55.1200 2.0000 1.0000
55.1800 9.0000 1.0000
55.2400 9.0000 1.0000
55.3000 9.0000 1.0000
55.3600 3.0000 1.0000
55.4200 8.0000 1.0000
55.4800 4.0000 1.0000
55.5400 3.0000 1.0000
55.6000 5.0000 1.0000
55.6600 6.0000 1.0000
55.7200 5.0000 1.0000
55.7800 10.0000 1.0000
55.8400 5.0000 1.0000
55.9000 7.0000 1.0000
55.9600 4.0000 1.0000
56.0200 4.0000 1.0000
56.0800 4.0000 1.0000
56.1400 7.0000 1.0000
56.2000 4.0000 1.0000
56.2600 8.0000 1.0000
56.3200 9.0000 1.0000
56.3800 2.0000 1.0000
56.4400 3.0000 1.0000
56.5000 5.0000 1.0000
56.5600 9.0000 1.0000
56.6200 2.0000 1.0000
56.6800 6.0000 1.0000
56.7400 6.0000 1.0000
56.8000 5.0000 1.0000
56.8600 4.0000 1.0000
56.9200 3.0000 1.0000
56.9800 5.0000 1.0000
57.0400 7.0000 1.0000
57.1000 6.0000 1.0000
57.1600 9.0000 1.0000
57.2200 10.0000 1.0000
57.2800 6.0000 1.0000
57.3400 8.0000 1.0000
57.4000 8.0000 1.0000
57.4600 8.0000 1.0000
57.5200 2.0000 1.0000
57.5800 4.0000 1.0000
57.6400 10.0000 1.0000
57.7000 6.0000 1.0000
57.7600 4.0000 1.0000
57.8200 6.0000 1.0000
57.8800 5.0000 1.0000
57.9400 2.0000 1.0000
58.0000 5.0000 1.0000
58.0600 6.0000 1.0000
58.1200 6.0000 1.0000
58.1800 6.0000 1.0000
58.2400 9.0000 1.0000
58.3000 2.0000 1.0000
58.3600 2.0000 1.0000
58.4200 7.0000 1.0000
58.4800 8.0000 1.0000
58.5400 10.0000 1.0000
58.6000 4.0000 1.0000
58.6600 4.0000 1.0000
58.7200 5.0000 1.0000
58.7800 4.0000 1.0000
58.8400 6.0000 1.0000
58.9000 4.0000 1.0000
58.9600 4.0000 1.0000
59.0200 7.0000 1.0000
59.0800 6.0000 1.0000
59.1400 2.0000 1.0000
59.2000 3.0000 1.0000
59.2600 5.0000 1.0000
59.3200 1.0000 1.0000
59.3800 6.0000 1.0000
59.4400 4.0000 1.0000
59.5000 3.0000 1.0000
59.5600 5.0000 1.0000
59.6200 5.0000 1.0000
59.6800 10.0000 1.0000
59.7400 5.0000 1.0000
59.8000 5.0000 1.0000
59.8600 9.0000 1.0000
59.9200 7.0000 1.0000
59.9800 4.0000 1.0000
60.0400 8.0000 1.0000
60.1000 6.0000 1.0000
60.1600 3.0000 1.0000
60.2200 6.0000 1.0000
60.2800 4.0000 1.0000
60.3400 4.0000 1.0000
60.4000 7.0000 1.0000
60.4600 1.0000 1.0000
60.5200 2.0000 1.0000
60.5800 8.0000 1.0000
60.6400 5.0000 1.0000
60.7000 3.0000 1.0000
60.7600 8.0000 1.0000
60.8200 4.0000 1.0000
60.8800 10.0000 1.0000
60.9400 2.0000 1.0000
61.0000 5.0000 1.0000
61.0600 9.0000 1.0000
61.1200 6.0000 1.0000
61.1800 4.0000 1.0000
61.2400 4.0000 1.0000
61.3000 5.0000 1.0000
61.3600 6.0000 1.0000
61.4200 4.0000 1.0000
61.4800 6.0000 1.0000
61.5400 3.0000 1.0000
61.6000 6.0000 1.0000
61.6600 4.0000 1.0000
61.7200 7.0000 1.0000
61.7800 6.0000 1.0000
61.8400 6.0000 1.0000
61.9000 2.0000 1.0000
61.9600 6.0000 1.0000
62.0200 4.0000 1.0000
62.0800 8.0000 1.0000
62.1400 9.0000 1.0000
62.2000 6.0000 1.0000
62.2600 11.0000 1.0000
62.3200 10.0000 1.0000
62.3800 11.0000 1.0000
62.4400 12.0000 1.0000
62.5000 8.0000 1.0000
62.5600 6.0000 1.0000
62.6200 14.0000 1.0000
62.6800 6.0000 1.0000
62.7400 10.0000 1.0000
62.8000 11.0000 1.0000
62.8600 8.0000 1.0000
62.9200 4.0000 1.0000
62.9800 4.0000 1.0000
63.0400 5.0000 1.0000
63.1000 4.0000 1.0000
63.1600 4.0000 1.0000
63.2200 3.0000 1.0000
63.2800 7.0000 1.0000
63.3400 3.0000 1.0000
63.4000 6.0000 1.0000
63.4600 10.0000 1.0000
63.5200 5.0000 1.0000
63.5800 6.0000 1.0000
63.6400 3.0000 1.0000
63.7000 8.0000 1.0000
63.7600 6.0000 1.0000
63.8200 9.0000 1.0000
63.8800 15.0000 1.0000
63.9400 12.0000 1.0000
64.0000 12.0000 1.0000
64.0600 11.0000 1.0000
64.1200 13.0000 1.0000
64.1800 12.0000 1.0000
64.2400 10.0000 1.0000
64.3000 13.0000 1.0000
64.3600 8.0000 1.0000
64.4200 5.0000 1.0000
64.4800 11.0000 1.0000
64.5400 3.0000 1.0000
64.6000 2.0000 1.0000
64.6600 4.0000 1.0000
64.7200 4.0000 1.0000
64.7800 6.0000 1.0000
64.8400 6.0000 1.0000
64.9000 7.0000 1.0000
64.9600 7.0000 1.0000
65.0200 8.0000 1.0000
65.0800 7.0000 1.0000
65.1400 5.0000 1.0000
65.2000 3.0000 1.0000
65.2600 4.0000 1.0000
65.3200 6.0000 1.0000
65.3800 3.0000 1.0000
65.4400 7.0000 1.0000
65.5000 3.0000 1.0000
65.5600 1.0000 1.0000
65.6200 1.0000 1.0000
65.6800 4.0000 1.0000
65.7400 4.0000 1.0000
65.8000 5.0000 1.0000
65.8600 6.0000 1.0000
65.9200 4.0000 1.0000
65.9800 9.0000 1.0000
66.0400 3.0000 1.0000
66.1000 3.0000 1.0000
66.1600 5.0000 1.0000
66.2200 5.0000 1.0000
66.2800 6.0000 1.0000
66.3400 7.0000 1.0000
66.4000 5.0000 1.0000
66.4600 6.0000 1.0000
66.5200 6.0000 1.0000
66.5800 4.0000 1.0000
66.6400 4.0000 1.0000
66.7000 5.0000 1.0000
66.7600 6.0000 1.0000
66.8200 0.0000 1.0000
66.8800 4.0000 1.0000
66.9400 8.0000 1.0000
67.0000 7.0000 1.0000
67.0600 6.0000 1.0000
67.1200 4.0000 1.0000
67.1800 4.0000 1.0000
67.2400 4.0000 1.0000
67.3000 4.0000 1.0000
67.3600 4.0000 1.0000
67.4200 8.0000 1.0000
67.4800 4.0000 1.0000
67.5400 3.0000 1.0000
67.6000 6.0000 1.0000
67.6600 6.0000 1.0000
67.7200 4.0000 1.0000
67.7800 2.0000 1.0000
67.8400 9.0000 1.0000
67.9000 5.0000 1.0000
67.9600 5.0000 1.0000
68.0200 6.0000 1.0000
68.0800 3.0000 1.0000
68.1400 3.0000 1.0000
68.2000 3.0000 1.0000
68.2600 4.0000 1.0000
68.3200 5.0000 1.0000
68.3800 7.0000 1.0000
68.4400 3.0000 1.0000
68.5000 4.0000 1.0000
68.5600 5.0000 1.0000
68.6200 6.0000 1.0000
68.6800 3.0000 1.0000
68.7400 4.0000 1.0000
68.8000 7.0000 1.0000
68.8600 8.0000 1.0000
68.9200 2.0000 1.0000
68.9800 1.0000 1.0000
69.0400 8.0000 1.0000
69.1000 7.0000 1.0000
69.1600 3.0000 1.0000
69.2200 5.0000 1.0000
69.2800 10.0000 1.0000
69.3400 3.0000 1.0000
69.4000 0.0000 1.0000
69.4600 9.0000 1.0000
69.5200 5.0000 1.0000
69.5800 5.0000 1.0000
69.6400 4.0000 1.0000
69.7000 5.0000 1.0000
69.7600 10.0000 1.0000
69.8200 8.0000 1.0000
69.8800 7.0000 1.0000
69.9400 6.0000 1.0000
70.0000 2.0000 1.0000
70.0600 5.0000 1.0000
70.1200 10.0000 1.0000
70.1800 4.0000 1.0000
70.2400 9.0000 1.0000
70.3000 4.0000 1.0000
70.3600 4.0000 1.0000
70.4200 4.0000 1.0000
70.4800 4.0000 1.0000
70.5400 2.0000 1.0000
70.6000 10.0000 1.0000
70.6600 5.0000 1.0000
70.7200 4.0000 1.0000
70.7800 6.0000 1.0000
70.8400 4.0000 1.0000
70.9000 6.0000 1.0000
70.9600 7.0000 1.0000
71.0200 2.0000 1.0000
71.0800 8.0000 1.0000
71.1400 8.0000 1.0000
71.2000 6.0000 1.0000
71.2600 6.0000 1.0000
71.3200 5.0000 1.0000
71.3800 8.0000 1.0000
71.4400 5.0000 1.0000
71.5000 2.0000 1.0000
71.5600 8.0000 1.0000
71.6200 7.0000 1.0000
71.6800 6.0000 1.0000
71.7400 4.0000 1.0000
71.8000 5.0000 1.0000
71.8600 6.0000 1.0000
71.9200 10.0000 1.0000
71.9800 6.0000 1.0000
72.0400 5.0000 1.0000
72.1000 5.0000 1.0000
72.1600 9.0000 1.0000
72.2200 10.0000 1.0000
72.2800 6.0000 1.0000
72.3400 6.0000 1.0000
72.4000 8.0000 1.0000
72.4600 5.0000 1.0000
72.5200 6.0000 1.0000
72.5800 7.0000 1.0000
72.6400 5.0000 1.0000
72.7000 4.0000 1.0000
72.7600 10.0000 1.0000
72.8200 5.0000 1.0000
72.8800 4.0000 1.0000
72.9400 6.0000 1.0000
73.0000 1.0000 1.0000
73.0600 7.0000 1.0000
73.1200 6.0000 1.0000
73.1800 4.0000 1.0000
73.2400 2.0000 1.0000
73.3000 2.0000 1.0000
73.3600 3.0000 1.0000
73.4200 2.0000 1.0000
73.4800 3.0000 1.0000
73.5400 6.0000 1.0000
73.6000 4.0000 1.0000
73.6600 1.0000 1.0000
73.7200 5.0000 1.0000
73.7800 7.0000 1.0000
73.8400 5.0000 1.0000
73.9000 4.0000 1.0000
73.9600 3.0000 1.0000
74.0200 8.0000 1.0000
74.0800 6.0000 1.0000
74.1400 2.0000 1.0000
74.2000 6.0000 1.0000
74.2600 7.0000 1.0000
74.3200 5.0000 1.0000
74.3800 3.0000 1.0000
74.4400 6.0000 1.0000
74.5000 4.0000 1.0000
74.5600 4.0000 1.0000
74.6200 3.0000 1.0000
74.6800 5.0000 1.0000
74.7400 4.0000 1.0000
74.8000 5.0000 1.0000
74.8600 6.0000 1.0000
74.9200 1.0000 1.0000
74.9800 3.0000 1.0000
75.0400 5.0000 1.0000
75.1000 7.0000 1.0000
75.1600 7.0000 1.0000
75.2200 5.0000 1.0000
75.2800 6.0000 1.0000
75.3400 4.0000 1.0000
75.4000 3.0000 1.0000
75.4600 9.0000 1.0000
75.5200 4.0000 1.0000
75.5800 6.0000 1.0000
75.6400 4.0000 1.0000
75.7000 3.0000 1.0000
75.7600 5.0000 1.0000
75.8200 3.0000 1.0000
75.8800 5.0000 1.0000
75.9400 3.0000 1.0000
76.0000 8.0000 1.0000
76.0600 9.0000 1.0000
76.1200 3.0000 1.0000
76.1800 3.0000 1.0000
76.2400 7.0000 1.0000
76.3000 1.0000 1.0000
76.3600 5.0000 1.0000
76.4200 4.0000 1.0000
76.4800 3.0000 1.0000
76.5400 6.0000 1.0000
76.6000 4.0000 1.0000
76.6600 5.0000 1.0000
76.7200 1.0000 1.0000
76.7800 4.0000 1.0000
76.8400 2.0000 1.0000
76.9000 3.0000 1.0000
76.9600 4.0000 1.0000
77.0200 7.0000 1.0000
77.0800 3.0000 1.0000
77.1400 7.0000 1.0000
77.2000 2.0000 1.0000
77.2600 3.0000 1.0000
77.3200 7.0000 1.0000
77.3800 8.0000 1.0000
77.4400 7.0000 1.0000
77.5000 5.0000 1.0000
77.5600 5.0000 1.0000
77.6200 7.0000 1.0000
77.6800 9.0000 1.0000
77.7400 7.0000 1.0000
77.8000 2.0000 1.0000
77.8600 7.0000 1.0000
77.9200 5.0000 1.0000
77.9800 4.0000 1.0000
78.0400 2.0000 1.0000
78.1000 5.0000 1.0000
78.1600 3.0000 1.0000
78.2200 7.0000 1.0000
78.2800 4.0000 1.0000
78.3400 2.0000 1.0000
78.4000 4.0000 1.0000
78.4600 6.0000 1.0000
78.5200 2.0000 1.0000
78.5800 6.0000 1.0000
78.6400 9.0000 1.0000
78.7000 8.0000 1.0000
78.7600 4.0000 1.0000
78.8200 10.0000 1.0000
78.8800 1.0000 1.0000
78.9400 3.0000 1.0000
79.0000 5.0000 1.0000
79.0600 5.0000 1.0000
79.1200 4.0000 1.0000
79.1800 5.0000 1.0000
79.2400 5.0000 1.0000
79.3000 7.0000 1.0000
79.3600 9.0000 1.0000
79.4200 8.0000 1.0000
79.4800 4.0000 1.0000
79.5400 5.0000 1.0000
79.6000 5.0000 1.0000
79.6600 8.0000 1.0000
79.7200 1.0000 1.0000
79.7800 8.0000 1.0000
79.8400 7.0000 1.0000
79.9000 6.0000 1.0000
79.9600 7.0000 1.0000
80.0200 11.0000 1.0000
80.0800 6.0000 1.0000
80.1400 3.0000 1.0000
80.2000 4.0000 1.0000
80.2600 3.0000 1.0000
80.3200 8.0000 1.0000
80.3800 4.0000 1.0000
80.4400 1.0000 1.0000
80.5000 6.0000 1.0000
80.5600 6.0000 1.0000
80.6200 7.0000 1.0000
80.6800 7.0000 1.0000
80.7400 2.0000 1.0000
80.8000 5.0000 1.0000
80.8600 7.0000 1.0000
80.9200 4.0000 1.0000
80.9800 6.0000 1.0000
81.0400 9.0000 1.0000
81.1000 5.0000 1.0000
81.1600 10.0000 1.0000
81.2200 6.0000 1.0000
81.2800 7.0000 1.0000
81.3400 5.0000 1.0000
81.4000 8.0000 1.0000
81.4600 2.0000 1.0000
81.5200 3.0000 1.0000
81.5800 5.0000 1.0000
81.6400 4.0000 1.0000
81.7000 2.0000 1.0000
81.7600 3.0000 1.0000
81.8200 7.0000 1.0000
81.8800 2.0000 1.0000
81.9400 4.0000 1.0000
82.0000 3.0000 1.0000
82.0600 2.0000 1.0000
82.1200 4.0000 1.0000
82.1800 5.0000 1.0000
82.2400 5.0000 1.0000
82.3000 7.0000 1.0000
82.3600 7.0000 1.0000
82.4200 6.0000 1.0000
82.4800 4.0000 1.0000
82.5400 3.0000 1.0000
82.6000 4.0000 1.0000
82.6600 6.0000 1.0000
82.7200 6.0000 1.0000
82.7800 3.0000 1.0000
82.8400 3.0000 1.0000
82.9000 9.0000 1.0000
82.9600 3.0000 1.0000
83.0200 11.0000 1.0000
83.0800 4.0000 1.0000
83.1400 7.0000 1.0000
83.2000 2.0000 1.0000
83.2600 4.0000 1.0000
83.3200 4.0000 1.0000
83.3800 9.0000 1.0000
83.4400 4.0000 1.0000
83.5000 3.0000 1.0000
83.5600 4.0000 1.0000
83.6200 5.0000 1.0000
83.6800 4.0000 1.0000
83.7400 8.0000 1.0000
83.8000 3.0000 1.0000
83.8600 2.0000 1.0000
83.9200 3.0000 1.0000
83.9800 4.0000 1.0000
84.0400 2.0000 1.0000
84.1000 4.0000 1.0000
84.1600 5.0000 1.0000
84.2200 4.0000 1.0000
84.2800 4.0000 1.0000
84.3400 6.0000 1.0000
84.4000 6.0000 1.0000
84.4600 6.0000 1.0000
84.5200 5.0000 1.0000
84.5800 5.0000 1.0000
84.6400 7.0000 1.0000
84.7000 3.0000 1.0000
84.7600 4.0000 1.0000
84.8200 4.0000 1.0000
84.8800 9.0000 1.0000
84.9400 10.0000 1.0000
85.0000 1.0000 1.0000
85.0600 3.0000 1.0000
85.1200 9.0000 1.0000
85.1800 10.0000 1.0000
85.2400 6.0000 1.0000
85.3000 7.0000 1.0000
85.3600 3.0000 1.0000
85.4200 10.0000 1.0000
85.4800 8.0000 1.0000
85.5400 7.0000 1.0000
85.6000 4.0000 1.0000
85.6600 7.0000 1.0000
85.7200 2.0000 1.0000
85.7800 5.0000 1.0000
85.8400 6.0000 1.0000
85.9000 6.0000 1.0000
85.9600 4.0000 1.0000
86.0200 7.0000 1.0000
86.0800 9.0000 1.0000
86.1400 5.0000 1.0000
86.2000 6.0000 1.0000
86.2600 6.0000 1.0000
86.3200 2.0000 1.0000
86.3800 3.0000 1.0000
86.4400 7.0000 1.0000
86.5000 1.0000 1.0000
86.5600 4.0000 1.0000
86.6200 3.0000 1.0000
86.6800 4.0000 1.0000
86.7400 5.0000 1.0000
86.8000 2.0000 1.0000
86.8600 3.0000 1.0000
86.9200 6.0000 1.0000
86.9800 8.0000 1.0000
87.0400 4.0000 1.0000
87.1000 3.0000 1.0000
87.1600 3.0000 1.0000
87.2200 4.0000 1.0000
87.2800 7.0000 1.0000
87.3400 5.0000 1.0000
87.4000 7.0000 1.0000
87.4600 3.0000 1.0000
87.5200 7.0000 1.0000
87.5800 8.0000 1.0000
87.6400 6.0000 1.0000
87.7000 4.0000 1.0000
87.7600 6.0000 1.0000
87.8200 6.0000 1.0000
87.8800 7.0000 1.0000
87.9400 2.0000 1.0000
88.0000 5.0000 1.0000
88.0600 5.0000 1.0000
88.1200 2.0000 1.0000
88.1800 7.0000 1.0000
88.2400 5.0000 1.0000
88.3000 8.0000 1.0000
88.3600 11.0000 1.0000
88.4200 8.0000 1.0000
88.4800 3.0000 1.0000
88.5400 7.0000 1.0000
88.6000 4.0000 1.0000
88.6600 7.0000 1.0000
88.7200 8.0000 1.0000
88.7800 2.0000 1.0000
88.8400 5.0000 1.0000
88.9000 7.0000 1.0000
88.9600 2.0000 1.0000
89.0200 7.0000 1.0000
89.0800 4.0000 1.0000
89.1400 8.0000 1.0000
89.2000 8.0000 1.0000
89.2600 5.0000 1.0000
89.3200 6.0000 1.0000
89.3800 5.0000 1.0000
89.4400 9.0000 1.0000
89.5000 5.0000 1.0000
89.5600 6.0000 1.0000
89.6200 10.0000 1.0000
89.6800 9.0000 1.0000
89.7400 2.0000 1.0000
89.8000 5.0000 1.0000
89.8600 4.0000 1.0000
89.9200 5.0000 1.0000
89.9800 4.0000 1.0000
90.0000 3.0000 1.0000
*RAS_INT_END
*RAS_DATA_END